Workbook

Sheet BETA
A1: Date | B1: Sensex closing px | C1: Axis Bank | D1: ICICI Bank | E1: IDFC Bank | F1: AU small finance Bank | G1: SBI Bank | H1: Bank of Baroda | I1: Sensex daily returns | J1: axis daily returns | K1: icici daily returns | L1: idfc daily returns | M1: au daily returns | N1: sbi daily retuns | O1: bob daily returns | P1: Sensex Log return | Q1: Axis Bank Log returns | R1: ICICI Bank Log returns | S1: IDFC Bank Log returns | T1: AU small finance Log returns | U1: SBI Log retuns | V1: Bank of Baroda Log returns
A2: 45748 | B2: 76024.51 | C2: 1085.6 | D2: 1318.45 | E2: 57.17 | F2: 529.9 | G2: 771.7 | H2: 228.58 | I2: =(B3/B2)-1 -> 0.01828897 | J2: =(C3/C2)-1 -> 0.015106853 | K2: =(D3/D2)-1 -> 0.022678145 | L2: =(E3/E2)-1 -> -0.038656638 | M2: =(F3/F2)-1 -> 0.008869598 | N2: =(G3/G2)-1 -> -0.00025916807 | O2: =(H3/H2)-1 -> -0.0002187418 | X2: Calculation of beta
A3: 45744 | B3: 77414.92 | C3: 1102 | D3: 1348.35 | E3: 54.96 | F3: 534.6 | G3: 771.5 | H3: 228.53 | I3: =(B4/B3)-1 -> 0.0024738125 | J3: =(C4/C3)-1 -> -0.0033121597 | K3: =(D4/D3)-1 -> -0.0086772722 | L3: =(E4/E3)-1 -> 0.036026201 | M3: =(F4/F3)-1 -> 0.037037037 | N3: =(G4/G3)-1 -> 0.001036941 | O3: =(H4/H3)-1 -> 0.010720693 | P3: =LN(B3/B2) -> 0.018123739 | Q3: =LN(C3/C2) -> 0.014993881 | R3: =LN(D3/D2) -> 0.022424818 | S3: =LN(E3/E2) -> -0.039423637 | T3: =LN(F3/F2) -> 0.0088304942 | U3: =LN(G3/G2) -> -0.00025920166 | V3: =LN(H3/H2) -> -0.00021876572 | X3: Overall (Slope formula)
A4: 45743 | B4: 77606.43 | C4: 1098.35 | D4: 1336.65 | E4: 56.94 | F4: 554.4 | G4: 772.3 | H4: 230.98 | I4: =(B5/B4)-1 -> -0.0040966966 | J4: =(C5/C4)-1 -> -0.0019119588 | K4: =(D5/D4)-1 -> -0.00056110425 | L4: =(E5/E4)-1 -> 0.0010537408 | M4: =(F5/F4)-1 -> 0.034902597 | N4: =(G5/G4)-1 -> -0.010747119 | O4: =(H5/H4)-1 -> -0.046064594 | P4: =LN(B4/B3) -> 0.0024707577 | Q4: =LN(C4/C3) -> -0.0033176571 | R4: =LN(D4/D3) -> -0.008715139 | S4: =LN(E4/E3) -> 0.035392434 | T4: =LN(F4/F3) -> 0.036367644 | U4: =LN(G4/G3) -> 0.0010364038 | V4: =LN(H4/H3) -> 0.010663634 | X4: Bank Name | Y4: Index | Z4: Beta
A5: 45742 | B5: 77288.5 | C5: 1096.25 | D5: 1335.9 | E5: 57 | F5: 573.75 | G5: 764 | H5: 220.34 | I5: =(B6/B5)-1 -> 0.0094281814 | J5: =(C6/C5)-1 -> 0.020342075 | K5: =(D6/D5)-1 -> 0.0058387604 | L5: =(E6/E5)-1 -> 0.0061403509 | M5: =(F6/F5)-1 -> -0.027625272 | N5: =(G6/G5)-1 -> 0.01158377 | O5: =(H6/H5)-1 -> 0.012389943 | P5: =LN(B5/B4) -> -0.0041051111 | Q5: =LN(C5/C4) -> -0.001913789 | R5: =LN(D5/D4) -> -0.00056126173 | S5: =LN(E5/E4) -> 0.001053186 | T5: =LN(F5/F4) -> 0.034307313 | U5: =LN(G5/G4) -> -0.010805286 | V5: =LN(H5/H4) -> -0.047159319 | X5: Axis Bank | Y5: Sensex | Z5: =SLOPE(Q3:Q1924,P3:P1924) -> 1.3492188
A6: 45741 | B6: 78017.19 | C6: 1118.55 | D6: 1343.7 | E6: 57.35 | F6: 557.9 | G6: 772.85 | H6: 223.07 | I6: =(B7/B6)-1 -> -0.00042054834 | J6: =(C7/C6)-1 -> -0.018506102 | K6: =(D7/D6)-1 -> 0.010753889 | L6: =(E7/E6)-1 -> 0.0094158675 | M6: =(F7/F6)-1 -> -0.014070622 | N6: =(G7/G6)-1 -> 0.010286602 | O6: =(H7/H6)-1 -> 0.0062760568 | P6: =LN(B6/B5) -> 0.0093840135 | Q6: =LN(C6/C5) -> 0.020137939 | R6: =LN(D6/D5) -> 0.0058217809 | S6: =LN(E6/E5) -> 0.0061215757 | T6: =LN(F6/F5) -> -0.028014027 | U6: =LN(G6/G5) -> 0.011517191 | V6: =LN(H6/H5) -> 0.012313816 | X6: ICICI Bank | Y6: Sensex | Z6: =SLOPE(R3:R1924,P3:P1924) -> 1.3091284
A7: 45740 | B7: 77984.38 | C7: 1097.85 | D7: 1358.15 | E7: 57.89 | F7: 550.05 | G7: 780.8 | H7: 224.47 | I7: =(B8/B7)-1 -> -0.013834437 | J7: =(C8/C7)-1 -> -0.025231134 | K7: =(D8/D7)-1 -> -0.01108125 | L7: =(E8/E7)-1 -> -0.027638625 | M7: =(F8/F7)-1 -> -0.01318062 | N7: =(G8/G7)-1 -> -0.035348361 | O7: =(H8/H7)-1 -> -0.034614871 | P7: =LN(B7/B6) -> -0.0004206368 | Q7: =LN(C7/C6) -> -0.018679482 | R7: =LN(D7/D6) -> 0.010696477 | S7: =LN(E7/E6) -> 0.0093718145 | T7: =LN(F7/F6) -> -0.014170552 | U7: =LN(G7/G6) -> 0.010234055 | V7: =LN(H7/H6) -> 0.0062564444 | X7: IDFC Bank | Y7: Sensex | Z7: =SLOPE(S3:S1924,P3:P1924) -> 1.2319305
A8: 45737 | B8: 76905.51 | C8: 1070.15 | D8: 1343.1 | E8: 56.29 | F8: 542.8 | G8: 753.2 | H8: 216.7 | I8: =(B9/B8)-1 -> -0.0072485053 | J8: =(C9/C8)-1 -> -0.014764285 | K8: =(D9/D8)-1 -> -0.015933289 | L8: =(E9/E8)-1 -> -0.010303784 | M8: =(F9/F8)-1 -> -0.032332351 | N8: =(G9/G8)-1 -> -0.0048459904 | O8: =(H9/H8)-1 -> -0.0048454084 | P8: =LN(B8/B7) -> -0.013931025 | Q8: =LN(C8/C7) -> -0.025554896 | R8: =LN(D8/D7) -> -0.011143105 | S8: =LN(E8/E7) -> -0.028027759 | T8: =LN(F8/F7) -> -0.013268255 | U8: =LN(G8/G7) -> -0.035988238 | V8: =LN(H8/H7) -> -0.035228159 | X8: AU small finance Bank | Y8: Sensex | Z8: =SLOPE(T3:T1924,P3:P1924) -> 0.86983526
A9: 45736 | B9: 76348.06 | C9: 1054.35 | D9: 1321.7 | E9: 55.71 | F9: 525.25 | G9: 749.55 | H9: 215.65 | I9: =(B10/B9)-1 -> -0.011775152 | J9: =(C10/C9)-1 -> -0.0021814388 | K9: =(D10/D9)-1 -> -0.0065067716 | L9: =(E10/E9)-1 -> -0.0052055286 | M9: =(F10/F9)-1 -> 0.0010471204 | N9: =(G10/G9)-1 -> -0.0059368955 | O9: =(H10/H9)-1 -> -0.0087642013 | P9: =LN(B9/B8) -> -0.0072749034 | Q9: =LN(C9/C8) -> -0.014874362 | R9: =LN(D9/D8) -> -0.016061588 | S9: =LN(E9/E8) -> -0.010357235 | T9: =LN(F9/F8) -> -0.032866588 | U9: =LN(G9/G8) -> -0.0048577703 | V9: =LN(H9/H8) -> -0.0048571854 | X9: SBI Bank | Y9: Sensex | Z9: =SLOPE(U3:U1924,P3:P1924) -> 1.2792067
A10: 45735 | B10: 75449.05 | C10: 1052.05 | D10: 1313.1 | E10: 55.42 | F10: 525.8 | G10: 745.1 | H10: 213.76 | I10: =(B11/B10)-1 -> -0.0019588053 | J10: =(C11/C10)-1 -> -0.0064635711 | K10: =(D11/D10)-1 -> -0.002475059 | L10: =(E11/E10)-1 -> -0.014435222 | M10: =(F11/F10)-1 -> -0.041460631 | N10: =(G11/G10)-1 -> -0.011273655 | O10: =(H11/H10)-1 -> -0.020677395 | P10: =LN(B10/B9) -> -0.011845028 | Q10: =LN(C10/C9) -> -0.0021838216 | R10: =LN(D10/D9) -> -0.0065280329 | S10: =LN(E10/E9) -> -0.0052191246 | T10: =LN(F10/F9) -> 0.0010465726 | U10: =LN(G10/G9) -> -0.0059545889 | V10: =LN(H10/H9) -> -0.0088028327 | X10: Bank of Baroda | Y10: Sensex | Z10: =SLOPE(V3:V1924,P3:P1924) -> 1.2706227
A11: 45734 | B11: 75301.26 | C11: 1045.25 | D11: 1309.85 | E11: 54.62 | F11: 504 | G11: 736.7 | H11: 209.34 | I11: =(B12/B11)-1 -> -0.015023786 | J11: =(C12/C11)-1 -> -0.010619469 | K11: =(D12/D11)-1 -> -0.031186777 | L11: =(E12/E11)-1 -> -0.03167338 | M11: =(F12/F11)-1 -> -0.024206349 | N11: =(G12/G11)-1 -> -0.018392833 | O11: =(H12/H11)-1 -> -0.017196905 | P11: =LN(B11/B10) -> -0.0019607263 | Q11: =LN(C11/C10) -> -0.0064845504 | R11: =LN(D11/D10) -> -0.002478127 | S11: =LN(E11/E10) -> -0.014540423 | T11: =LN(F11/F10) -> -0.042344644 | U11: =LN(G11/G10) -> -0.011337684 | V11: =LN(H11/H10) -> -0.020894166
A12: 45733 | B12: 74169.95 | C12: 1034.15 | D12: 1269 | E12: 52.89 | F12: 491.8 | G12: 723.15 | H12: 205.74 | I12: =(B13/B12)-1 -> -0.0045980886 | J12: =(C13/C12)-1 -> -0.023159116 | K12: =(D13/D12)-1 -> -0.014933018 | L12: =(E13/E12)-1 -> 0.011155228 | M12: =(F13/F12)-1 -> 0.022468483 | N12: =(G13/G12)-1 -> 0.0064993432 | O12: =(H13/H12)-1 -> -0.0010693108 | P12: =LN(B12/B11) -> -0.015137786 | Q12: =LN(C12/C11) -> -0.010676258 | R12: =LN(D12/D11) -> -0.031683438 | S12: =LN(E12/E11) -> -0.032185831 | T12: =LN(F12/F11) -> -0.024504138 | U12: =LN(G12/G11) -> -0.018564084 | V12: =LN(H12/H11) -> -0.017346489 | X12: Regression
A13: 45729 | B13: 73828.91 | C13: 1010.2 | D13: 1250.05 | E13: 53.48 | F13: 502.85 | G13: 727.85 | H13: 205.52 | I13: =(B14/B13)-1 -> 0.002720479 | J13: =(C14/C13)-1 -> 0.00098990299 | K13: =(D14/D13)-1 -> -0.0048798048 | L13: =(E14/E13)-1 -> 0.021503366 | M13: =(F14/F13)-1 -> 0.0086506911 | N13: =(G14/G13)-1 -> -0.0065947654 | O13: =(H14/H13)-1 -> -0.015181004 | P13: =LN(B13/B12) -> -0.0046086923 | Q13: =LN(C13/C12) -> -0.023431502 | R13: =LN(D13/D12) -> -0.015045638 | S13: =LN(E13/E12) -> 0.011093467 | T13: =LN(F13/F12) -> 0.022219785 | U13: =LN(G13/G12) -> 0.0064783135 | V13: =LN(H13/H12) -> -0.0010698829 | X13: Bank Name | Y13: Index | Z13: Beta
A14: 45728 | B14: 74029.76 | C14: 1011.2 | D14: 1243.95 | E14: 54.63 | F14: 507.2 | G14: 723.05 | H14: 202.4 | I14: =(B15/B14)-1 -> 0.00098014636 | J14: =(C15/C14)-1 -> 0.014289953 | K14: =(D15/D14)-1 -> 0.0011656417 | L14: =(E15/E14)-1 -> 0.013362621 | M14: =(F15/F14)-1 -> 0.029376972 | N14: =(G15/G14)-1 -> 0.0094046055 | O14: =(H15/H14)-1 -> 0.00079051383 | P14: =LN(B14/B13) -> 0.0027167852 | Q14: =LN(C14/C13) -> 0.00098941336 | R14: =LN(D14/D13) -> -0.0048917499 | S14: =LN(E14/E13) -> 0.02127543 | T14: =LN(F14/F13) -> 0.0086134882 | U14: =LN(G14/G13) -> -0.0066166069 | V14: =LN(H14/H13) -> -0.015297415 | X14: Axis Bank | Y14: Sensex | Z14: ='Regression-Axis'!F20 -> 1.3492188
A15: 45727 | B15: 74102.32 | C15: 1025.65 | D15: 1245.4 | E15: 55.36 | F15: 522.1 | G15: 729.85 | H15: 202.56 | I15: =(B16/B15)-1 -> 0.00017340888 | J15: =(C16/C15)-1 -> 0.009944913 | K15: =(D16/D15)-1 -> -0.024530271 | L15: =(E16/E15)-1 -> 0.01824422 | M15: =(F16/F15)-1 -> 0.032081977 | N15: =(G16/G15)-1 -> -0.0013016373 | O15: =(H16/H15)-1 -> 0.007257109 | P15: =LN(B15/B14) -> 0.00097966633 | Q15: =LN(C15/C14) -> 0.014188814 | R15: =LN(D15/D14) -> 0.0011649629 | S15: =LN(E15/E14) -> 0.013274129 | T15: =LN(F15/F14) -> 0.028953737 | U15: =LN(G15/G14) -> 0.0093606575 | V15: =LN(H15/H14) -> 0.00079020154 | X15: ICICI Bank | Y15: Sensex | Z15: ='Regression-ICICI'!F20 -> 1.3091284
A16: 45726 | B16: 74115.17 | C16: 1035.85 | D16: 1214.85 | E16: 56.37 | F16: 538.85 | G16: 728.9 | H16: 204.03 | I16: =(B17/B16)-1 -> 0.0029334076 | J16: =(C17/C16)-1 -> 0.0017377033 | K16: =(D17/D16)-1 -> -0.00024694407 | L16: =(E17/E16)-1 -> 0.017207735 | M16: =(F17/F16)-1 -> 0.010114132 | N16: =(G17/G16)-1 -> 0.0052819317 | O16: =(H17/H16)-1 -> 0.0091653188 | P16: =LN(B16/B15) -> 0.00017339384 | Q16: =LN(C16/C15) -> 0.0098957878 | R16: =LN(D16/D15) -> -0.024836151 | S16: =LN(E16/E15) -> 0.018079791 | T16: =LN(F16/F15) -> 0.031578099 | U16: =LN(G16/G15) -> -0.0013024852 | V16: =LN(H16/H15) -> 0.0072309029 | X16: IDFC Bank | Y16: Sensex | Z16: ='Regression-IDFC'!F20 -> 1.2319305
A17: 45723 | B17: 74332.58 | C17: 1037.65 | D17: 1214.55 | E17: 57.34 | F17: 544.3 | G17: 732.75 | H17: 205.9 | I17: =(B18/B17)-1 -> 0.00010103241 | J17: =(C18/C17)-1 -> -0.0034211921 | K17: =(D18/D17)-1 -> 0.0028817257 | L17: =(E18/E17)-1 -> 0.007499128 | M17: =(F18/F17)-1 -> 0.016351277 | N17: =(G18/G17)-1 -> -0.00095530536 | O17: =(H18/H17)-1 -> 0.0061194755 | P17: =LN(B17/B16) -> 0.0029291135 | Q17: =LN(C17/C16) -> 0.0017361953 | R17: =LN(D17/D16) -> -0.00024697456 | S17: =LN(E17/E16) -> 0.017061358 | T17: =LN(F17/F16) -> 0.010063326 | U17: =LN(G17/G16) -> 0.0052680312 | V17: =LN(H17/H16) -> 0.0091235722 | X17: AU small finance Bank | Y17: Sensex | Z17: ='Regression-AU Small'!F20 -> 0.86898713
A18: 45722 | B18: 74340.09 | C18: 1034.1 | D18: 1218.05 | E18: 57.77 | F18: 553.2 | G18: 732.05 | H18: 207.16 | I18: =(B19/B18)-1 -> -0.0082036489 | J18: =(C19/C18)-1 -> -0.019002031 | K18: =(D19/D18)-1 -> -0.0019293132 | L18: =(E19/E18)-1 -> 0.0031158041 | M18: =(F19/F18)-1 -> -0.012201735 | N18: =(G19/G18)-1 -> -0.0023222457 | O18: =(H19/H18)-1 -> -0.0093647422 | P18: =LN(B18/B17) -> 0.00010102731 | Q18: =LN(C18/C17) -> -0.0034270578 | R18: =LN(D18/D17) -> 0.0028775815 | S18: =LN(E18/E17) -> 0.0074711493 | T18: =LN(F18/F17) -> 0.016219034 | U18: =LN(G18/G17) -> -0.00095576195 | V18: =LN(H18/H17) -> 0.0061008275 | X18: SBI Bank | Y18: Sensex | Z18: ='Regression-SBI'!F20 -> 1.2792067
A19: 45721 | B19: 73730.23 | C19: 1014.45 | D19: 1215.7 | E19: 57.95 | F19: 546.45 | G19: 730.35 | H19: 205.22 | I19: =(B20/B19)-1 -> -0.010040658 | J19: =(C20/C19)-1 -> -0.012469811 | K19: =(D20/D19)-1 -> -0.0043596282 | L19: =(E20/E19)-1 -> -0.019327006 | M19: =(F20/F19)-1 -> 0.0034769878 | N19: =(G20/G19)-1 -> -0.019579654 | O19: =(H20/H19)-1 -> -0.045317221 | P19: =LN(B19/B18) -> -0.008237484 | Q19: =LN(C19/C18) -> -0.01918489 | R19: =LN(D19/D18) -> -0.0019311768 | S19: =LN(E19/E18) -> 0.00311096 | T19: =LN(F19/F18) -> -0.012276788 | U19: =LN(G19/G18) -> -0.0023249463 | V19: =LN(H19/H18) -> -0.0094088671 | X19: Bank of Baroda | Y19: Sensex | Z19: ='Regression-Bank of Baroda'!F20 -> 1.2706227
A20: 45720 | B20: 72989.93 | C20: 1001.8 | D20: 1210.4 | E20: 56.83 | F20: 548.35 | G20: 716.05 | H20: 195.92 | I20: =(B21/B20)-1 -> 0.0013153869 | J20: =(C21/C20)-1 -> 0.0054402076 | K20: =(D21/D20)-1 -> -0.0034699273 | L20: =(E21/E20)-1 -> 0.015132852 | M20: =(F21/F20)-1 -> 0.016868788 | N20: =(G21/G20)-1 -> -0.028978423 | O20: =(H21/H20)-1 -> -5.1041241e-05 | P20: =LN(B20/B19) -> -0.010091405 | Q20: =LN(C20/C19) -> -0.012548212 | R20: =LN(D20/D19) -> -0.0043691591 | S20: =LN(E20/E19) -> -0.019516214 | T20: =LN(F20/F19) -> 0.0034709571 | U20: =LN(G20/G19) -> -0.019773874 | V20: =LN(H20/H19) -> -0.046376162
A21: 45719 | B21: 73085.94 | C21: 1007.25 | D21: 1206.2 | E21: 57.69 | F21: 557.6 | G21: 695.3 | H21: 195.91 | I21: =(B22/B21)-1 -> 0.0015346317 | J21: =(C22/C21)-1 -> 0.0082402581 | K21: =(D22/D21)-1 -> -0.0017410048 | L21: =(E22/E21)-1 -> 0.012133819 | M21: =(F22/F21)-1 -> 0.014526542 | N21: =(G22/G21)-1 -> -0.0093484827 | O21: =(H22/H21)-1 -> 0.0059210862 | P21: =LN(B21/B20) -> 0.0013145226 | Q21: =LN(C21/C20) -> 0.0054254631 | R21: =LN(D21/D20) -> -0.0034759615 | S21: =LN(E21/E20) -> 0.015019493 | T21: =LN(F21/F20) -> 0.01672809 | U21: =LN(G21/G20) -> -0.02940659 | V21: =LN(H21/H20) -> -5.1042544e-05 | X21: Last 1 year (27th March 2024- 28th March 2025)
A22: 45716 | B22: 73198.1 | C22: 1015.55 | D22: 1204.1 | E22: 58.39 | F22: 565.7 | G22: 688.8 | H22: 197.07 | I22: =(B23/B22)-1 -> 0.01932195 | J22: =(C23/C22)-1 -> 0.0011323913 | K22: =(D23/D22)-1 -> 0.015239598 | L22: =(E23/E22)-1 -> 0.014214763 | M22: =(F23/F22)-1 -> -0.015909493 | N22: =(G23/G22)-1 -> 0.021922184 | O22: =(H23/H22)-1 -> 0.031004212 | P22: =LN(B22/B21) -> 0.0015334554 | Q22: =LN(C22/C21) -> 0.0082064926 | R22: =LN(D22/D21) -> -0.0017425221 | S22: =LN(E22/E21) -> 0.012060794 | T22: =LN(F22/F21) -> 0.014422043 | U22: =LN(G22/G21) -> -0.009392454 | V22: =LN(H22/H21) -> 0.0059036255 | X22: Bank Name | Y22: Index | Z22: Beta
A23: 45715 | B23: 74612.43 | C23: 1016.7 | D23: 1222.45 | E23: 59.22 | F23: 556.7 | G23: 703.9 | H23: 203.18 | I23: =(B24/B23)-1 -> -0.00013818073 | J23: =(C24/C23)-1 -> -0.0074751647 | K23: =(D24/D23)-1 -> 0.0013906499 | L23: =(E24/E23)-1 -> -0.0069233367 | M23: =(F24/F23)-1 -> -0.058289923 | N23: =(G24/G23)-1 -> 0.0099445944 | O23: =(H24/H23)-1 -> 0.0078255734 | P23: =LN(B23/B22) -> 0.019137651 | Q23: =LN(C23/C22) -> 0.0011317506 | R23: =LN(D23/D22) -> 0.015124642 | S23: =LN(E23/E22) -> 0.01411468 | T23: =LN(F23/F22) -> -0.016037407 | U23: =LN(G23/G22) -> 0.021685348 | V23: =LN(H23/H22) -> 0.03053329 | X23: Axis Bank | Y23: Sensex | Z23: =SLOPE(Q3:Q253,P3:P253) -> 1.1068075
A24: 45713 | B24: 74602.12 | C24: 1009.1 | D24: 1224.15 | E24: 58.81 | F24: 524.25 | G24: 710.9 | H24: 204.77 | I24: =(B25/B24)-1 -> -0.0019799705 | J24: =(C25/C24)-1 -> 0.00094143296 | K24: =(D25/D24)-1 -> -0.0047379815 | L24: =(E25/E24)-1 -> 0.018534263 | M24: =(F25/F24)-1 -> 0.01669051 | N24: =(G25/G24)-1 -> 0.0077366718 | O24: =(H25/H24)-1 -> 0.018850418 | P24: =LN(B24/B23) -> -0.00013819028 | Q24: =LN(C24/C23) -> -0.0075032438 | R24: =LN(D24/D23) -> 0.0013896839 | S24: =LN(E24/E23) -> -0.0069474142 | T24: =LN(F24/F23) -> -0.060057825 | U24: =LN(G24/G23) -> 0.0098954723 | V24: =LN(H24/H23) -> 0.0077951124 | X24: ICICI Bank | Y24: Sensex | Z24: =SLOPE(R3:R253,P3:P253) -> 1.0324254
A25: 45712 | B25: 74454.41 | C25: 1010.05 | D25: 1218.35 | E25: 59.9 | F25: 533 | G25: 716.4 | H25: 208.63 | I25: =(B26/B25)-1 -> 0.011505699 | J25: =(C26/C25)-1 -> -0.001089055 | K25: =(D26/D25)-1 -> 0.01198342 | L25: =(E26/E25)-1 -> 0.012186978 | M25: =(F26/F25)-1 -> 0.008630394 | N25: =(G26/G25)-1 -> 0.0078168621 | O25: =(H26/H25)-1 -> 0.0078608062 | P25: =LN(B25/B24) -> -0.0019819333 | Q25: =LN(C25/C24) -> 0.00094099009 | R25: =LN(D25/D24) -> -0.0047492413 | S25: =LN(E25/E24) -> 0.018364597 | T25: =LN(F25/F24) -> 0.016552754 | U25: =LN(G25/G24) -> 0.0077068973 | V25: =LN(H25/H24) -> 0.01867495 | X25: IDFC Bank | Y25: Sensex | Z25: =SLOPE(S3:S253,P3:P253) -> 0.99457593
A26: 45709 | B26: 75311.06 | C26: 1008.95 | D26: 1232.95 | E26: 60.63 | F26: 537.6 | G26: 722 | H26: 210.27 | I26: =(B27/B26)-1 -> 0.0056419336 | J26: =(C27/C26)-1 -> 0.0081768175 | K26: =(D27/D26)-1 -> 0.013788069 | L26: =(E27/E26)-1 -> 0.012040244 | M26: =(F27/F26)-1 -> -0.0047433036 | N26: =(G27/G26)-1 -> 0.01066482 | O26: =(H27/H26)-1 -> 0.015694108 | P26: =LN(B26/B25) -> 0.011440011 | Q26: =LN(C26/C25) -> -0.0010896484 | R26: =LN(D26/D25) -> 0.011912188 | S26: =LN(E26/E25) -> 0.012113315 | T26: =LN(F26/F25) -> 0.008593365 | U26: =LN(G26/G25) -> 0.0077864687 | V26: =LN(H26/H25) -> 0.007830071 | X26: AU small finance Bank | Y26: Sensex | Z26: =SLOPE(T3:T253,P3:P253) -> 0.56786072
A27: 45708 | B27: 75735.96 | C27: 1017.2 | D27: 1249.95 | E27: 61.36 | F27: 535.05 | G27: 729.7 | H27: 213.57 | I27: =(B28/B27)-1 -> 0.0026832696 | J27: =(C28/C27)-1 -> -0.0057510814 | K27: =(D28/D27)-1 -> 0.0093603744 | L27: =(E28/E27)-1 -> -0.022327249 | M27: =(F28/F27)-1 -> -0.017568452 | N27: =(G28/G27)-1 -> -0.0032890229 | O27: =(H28/H27)-1 -> -0.02191319 | P27: =LN(B27/B26) -> 0.0056260775 | Q27: =LN(C27/C26) -> 0.0081435684 | R27: =LN(D27/D26) -> 0.013693879 | S27: =LN(E27/E26) -> 0.011968337 | T27: =LN(F27/F26) -> -0.0047545887 | U27: =LN(G27/G26) -> 0.010608352 | V27: =LN(H27/H26) -> 0.015572229 | X27: SBI Bank | Y27: Sensex | Z27: =SLOPE(U3:U253,P3:P253) -> 1.4443737
A28: 45707 | B28: 75939.18 | C28: 1011.35 | D28: 1261.65 | E28: 59.99 | F28: 525.65 | G28: 727.3 | H28: 208.89 | I28: =(B29/B28)-1 -> 0.00037148149 | J28: =(C29/C28)-1 -> -0.017006971 | K28: =(D29/D28)-1 -> -0.014742599 | L28: =(E29/E28)-1 -> -0.0078346391 | M28: =(F29/F28)-1 -> -0.044230952 | N28: =(G29/G28)-1 -> -0.0020624227 | O28: =(H29/H28)-1 -> -0.013404184 | P28: =LN(B28/B27) -> 0.0026796761 | Q28: =LN(C28/C27) -> -0.0057676825 | R28: =LN(D28/D27) -> 0.0093168376 | S28: =LN(E28/E27) -> -0.022580275 | T28: =LN(F28/F27) -> -0.017724608 | U28: =LN(G28/G27) -> -0.0032944436 | V28: =LN(H28/H27) -> -0.02215685 | X28: Bank of Baroda | Y28: Sensex | Z28: =SLOPE(V3:V253,P3:P253) -> 1.6295225
A29: 45706 | B29: 75967.39 | C29: 994.15 | D29: 1243.05 | E29: 59.52 | F29: 502.4 | G29: 725.8 | H29: 206.09 | I29: =(B30/B29)-1 -> 0.00038792961 | J29: =(C30/C29)-1 -> -0.0012070613 | K29: =(D30/D29)-1 -> 0.0065162302 | L29: =(E30/E29)-1 -> 0.033266129 | M29: =(F30/F29)-1 -> 0.039112261 | N29: =(G30/G29)-1 -> 0.002617801 | O29: =(H30/H29)-1 -> 0.0042214566 | P29: =LN(B29/B28) -> 0.00037141251 | Q29: =LN(C29/C28) -> -0.01715325 | R29: =LN(D29/D28) -> -0.014852351 | S29: =LN(E29/E28) -> -0.0078654911 | T29: =LN(F29/F28) -> -0.045238977 | U29: =LN(G29/G28) -> -0.0020645524 | V29: =LN(H29/H28) -> -0.013494831
A30: 45705 | B30: 75996.86 | C30: 992.95 | D30: 1251.15 | E30: 61.5 | F30: 522.05 | G30: 727.7 | H30: 206.96 | I30: =(B31/B30)-1 -> -0.00075858397 | J30: =(C31/C30)-1 -> 0.0045823053 | K30: =(D31/D30)-1 -> 0.0071534189 | L30: =(E31/E30)-1 -> -0.014634146 | M30: =(F31/F30)-1 -> 0.024614501 | N30: =(G31/G30)-1 -> -0.0076267693 | O30: =(H31/H30)-1 -> -0.0086973328 | P30: =LN(B30/B29) -> 0.00038785439 | Q30: =LN(C30/C29) -> -0.0012077904 | R30: =LN(D30/D29) -> 0.0064950914 | S30: =LN(E30/E29) -> 0.032724784 | T30: =LN(F30/F29) -> 0.038366754 | U30: =LN(G30/G29) -> 0.0026143806 | V30: =LN(H30/H29) -> 0.0042125713
A31: 45702 | B31: 75939.21 | C31: 997.5 | D31: 1260.1 | E31: 60.6 | F31: 534.9 | G31: 722.15 | H31: 205.16 | I31: =(B32/B31)-1 -> 0.0026305251 | J31: =(C32/C31)-1 -> 0.010726817 | K31: =(D32/D31)-1 -> -0.0088881835 | L31: =(E32/E31)-1 -> 0.014686469 | M31: =(F32/F31)-1 -> 0.033931576 | N31: =(G32/G31)-1 -> 0.0076161462 | O31: =(H32/H31)-1 -> 0.027490739 | P31: =LN(B31/B30) -> -0.00075887184 | Q31: =LN(C31/C30) -> 0.0045718385 | R31: =LN(D31/D30) -> 0.0071279545 | S31: =LN(E31/E30) -> -0.014742282 | T31: =LN(F31/F30) -> 0.024316445 | U31: =LN(G31/G30) -> -0.0076560018 | V31: =LN(H31/H30) -> -0.0087353754
A32: 45701 | B32: 76138.97 | C32: 1008.2 | D32: 1248.9 | E32: 61.49 | F32: 553.05 | G32: 727.65 | H32: 210.8 | I32: =(B33/B32)-1 -> 0.00042172885 | J32: =(C33/C32)-1 -> -0.0012894267 | K32: =(D33/D32)-1 -> 0.0023220434 | L32: =(E33/E32)-1 -> 0.010896081 | M32: =(F33/F32)-1 -> 0.002441009 | N32: =(G33/G32)-1 -> 0.007558579 | O32: =(H33/H32)-1 -> 0.0082542694 | P32: =LN(B32/B31) -> 0.0026270714 | Q32: =LN(C32/C31) -> 0.010669693 | R32: =LN(D32/D31) -> -0.008927919 | S32: =LN(E32/E31) -> 0.014579667 | T32: =LN(F32/F31) -> 0.0333686 | U32: =LN(G32/G31) -> 0.0075872898 | V32: =LN(H32/H31) -> 0.027119654
A33: 45700 | B33: 76171.08 | C33: 1006.9 | D33: 1251.8 | E33: 62.16 | F33: 554.4 | G33: 733.15 | H33: 212.54 | I33: =(B34/B33)-1 -> 0.0016084845 | J33: =(C34/C33)-1 -> 0.00049657364 | K33: =(D34/D33)-1 -> 0.00075890717 | L33: =(E34/E33)-1 -> -0.0083655084 | M33: =(F34/F33)-1 -> 0.029401154 | N33: =(G34/G33)-1 -> -0.0027961536 | O33: =(H34/H33)-1 -> -0.0082807942 | P33: =LN(B33/B32) -> 0.00042163994 | Q33: =LN(C33/C32) -> -0.0012902587 | R33: =LN(D33/D32) -> 0.0023193516 | S33: =LN(E33/E32) -> 0.010837146 | T33: =LN(F33/F32) -> 0.0024380345 | U33: =LN(G33/G32) -> 0.0075301561 | V33: =LN(H33/H32) -> 0.0082203893
A34: 45699 | B34: 76293.6 | C34: 1007.4 | D34: 1252.75 | E34: 61.64 | F34: 570.7 | G34: 731.1 | H34: 210.78 | I34: =(B35/B34)-1 -> 0.013345811 | J34: =(C35/C34)-1 -> 0.0043180465 | K34: =(D35/D34)-1 -> 0.0078627021 | L34: =(E35/E34)-1 -> 0.020603504 | M34: =(F35/F34)-1 -> 0.015857719 | N34: =(G35/G34)-1 -> 0.0077964711 | O34: =(H35/H34)-1 -> 0.02111206 | P34: =LN(B34/B33) -> 0.0016071923 | Q34: =LN(C34/C33) -> 0.00049645039 | R34: =LN(D34/D33) -> 0.00075861935 | S34: =LN(E34/E33) -> -0.0084006956 | T34: =LN(F34/F33) -> 0.02897723 | U34: =LN(G34/G33) -> -0.0028000701 | V34: =LN(H34/H33) -> -0.0083152704
A35: 45698 | B35: 77311.8 | C35: 1011.75 | D35: 1262.6 | E35: 62.91 | F35: 579.75 | G35: 736.8 | H35: 215.23 | I35: =(B36/B35)-1 -> 0.0070932251 | J35: =(C36/C35)-1 -> 0.012206573 | K35: =(D36/D35)-1 -> -0.0045144939 | L35: =(E36/E35)-1 -> 0.018756954 | M35: =(F36/F35)-1 -> 0.021302285 | N35: =(G36/G35)-1 -> 0.00054288817 | O35: =(H36/H35)-1 -> 0.0050643498 | P35: =LN(B35/B34) -> 0.013257541 | Q35: =LN(C35/C34) -> 0.0043087504 | R35: =LN(D35/D34) -> 0.0078319521 | S35: =LN(E35/E34) -> 0.020394123 | T35: =LN(F35/F34) -> 0.015733299 | U35: =LN(G35/G34) -> 0.0077662356 | V35: =LN(H35/H34) -> 0.020892288
A36: 45695 | B36: 77860.19 | C36: 1024.1 | D36: 1256.9 | E36: 64.09 | F36: 592.1 | G36: 737.2 | H36: 216.32 | I36: =(B37/B36)-1 -> 0.0025426344 | J36: =(C37/C36)-1 -> -0.0033199883 | K36: =(D37/D36)-1 -> 0.012331928 | L36: =(E37/E36)-1 -> -0.005617101 | M36: =(F37/F36)-1 -> -0.0098800878 | N36: =(G37/G36)-1 -> 0.020415084 | O36: =(H37/H36)-1 -> 0.015671228 | P36: =LN(B36/B35) -> 0.0070681865 | Q36: =LN(C36/C35) -> 0.012132673 | R36: =LN(D36/D35) -> -0.004524715 | S36: =LN(E36/E35) -> 0.018583212 | T36: =LN(F36/F35) -> 0.021078563 | U36: =LN(G36/G35) -> 0.00054274085 | V36: =LN(H36/H35) -> 0.0050515691
A37: 45694 | B37: 78058.16 | C37: 1020.7 | D37: 1272.4 | E37: 63.73 | F37: 586.25 | G37: 752.25 | H37: 219.71 | I37: =(B38/B37)-1 -> 0.0027302719 | J37: =(C38/C37)-1 -> -0.0072499265 | K37: =(D38/D37)-1 -> -0.003693807 | L37: =(E38/E37)-1 -> -0.0062764789 | M37: =(F38/F37)-1 -> 0.015948827 | N37: =(G38/G37)-1 -> 0.018344965 | O37: =(H38/H37)-1 -> 0.0014109508 | P37: =LN(B37/B36) -> 0.0025394074 | Q37: =LN(C37/C36) -> -0.0033255117 | R37: =LN(D37/D36) -> 0.012256509 | S37: =LN(E37/E36) -> -0.0056329362 | T37: =LN(F37/F36) -> -0.0099292198 | U37: =LN(G37/G36) -> 0.02020949 | V37: =LN(H37/H36) -> 0.015549702
A38: 45693 | B38: 78271.28 | C38: 1013.3 | D38: 1267.7 | E38: 63.33 | F38: 595.6 | G38: 766.05 | H38: 220.02 | I38: =(B39/B38)-1 -> 0.0039929077 | J38: =(C39/C38)-1 -> 0.0019737491 | K38: =(D39/D38)-1 -> 0.00039441508 | L38: =(E39/E38)-1 -> -0.019106269 | M38: =(F39/F38)-1 -> 0.0071356615 | N38: =(G39/G38)-1 -> 0.017165981 | O38: =(H39/H38)-1 -> -0.032406145 | P38: =LN(B38/B37) -> 0.0027265515 | Q38: =LN(C38/C37) -> -0.007276335 | R38: =LN(D38/D37) -> -0.0037006459 | S38: =LN(E38/E37) -> -0.0062962588 | T38: =LN(F38/F37) -> 0.015822981 | U38: =LN(G38/G37) -> 0.018178726 | V38: =LN(H38/H37) -> 0.0014099563
A39: 45692 | B39: 78583.81 | C39: 1015.3 | D39: 1268.2 | E39: 62.12 | F39: 599.85 | G39: 779.2 | H39: 212.89 | I39: =(B40/B39)-1 -> -0.017778089 | J39: =(C40/C39)-1 -> -0.025509702 | K39: =(D40/D39)-1 -> -0.011985491 | L39: =(E40/E39)-1 -> 0.0022537025 | M39: =(F40/F39)-1 -> 0.015087105 | N39: =(G40/G39)-1 -> -0.023421458 | O39: =(H40/H39)-1 -> -0.023016581 | P39: =LN(B39/B38) -> 0.0039849572 | Q39: =LN(C39/C38) -> 0.0019718039 | R39: =LN(D39/D38) -> 0.00039433732 | S39: =LN(E39/E38) -> -0.019291152 | T39: =LN(F39/F38) -> 0.0071103232 | U39: =LN(G39/G38) -> 0.017020311 | V39: =LN(H39/H38) -> -0.032942851
A40: 45691 | B40: 77186.74 | C40: 989.4 | D40: 1253 | E40: 62.26 | F40: 608.9 | G40: 760.95 | H40: 207.99 | I40: =(B41/B40)-1 -> 0.0041356844 | J40: =(C41/C40)-1 -> 0.0088437437 | K40: =(D41/D40)-1 -> 0.0020351157 | L40: =(E41/E40)-1 -> -0.0049791198 | M40: =(F41/F40)-1 -> -0.012892101 | N40: =(G41/G40)-1 -> 0.0066364413 | O40: =(H41/H40)-1 -> 0.013702582 | P40: =LN(B40/B39) -> -0.017938018 | Q40: =LN(C40/C39) -> -0.025840716 | R40: =LN(D40/D39) -> -0.012057896 | S40: =LN(E40/E39) -> 0.0022511667 | T40: =LN(F40/F39) -> 0.014974427 | U40: =LN(G40/G39) -> -0.0237001 | V40: =LN(H40/H39) -> -0.023285599
...

Sheet Regression-Axis
B1: Sensex Log return | C1: Axis Bank Log returns
B3: =BETA!P3 -> 0.018123739 | C3: =BETA!Q3 -> 0.014993881 | E3: SUMMARY OUTPUT
B4: =BETA!P4 -> 0.0024707577 | C4: =BETA!Q4 -> -0.0033176571
B5: =BETA!P5 -> -0.0041051111 | C5: =BETA!Q5 -> -0.001913789 | E5: Regression Statistics
B6: =BETA!P6 -> 0.0093840135 | C6: =BETA!Q6 -> 0.020137939 | E6: Multiple R | F6: 0.68686311
B7: =BETA!P7 -> -0.0004206368 | C7: =BETA!Q7 -> -0.018679482 | E7: R Square | F7: 0.47178094
B8: =BETA!P8 -> -0.013931025 | C8: =BETA!Q8 -> -0.025554896 | E8: Adjusted R Square | F8: 0.47150582
B9: =BETA!P9 -> -0.0072749034 | C9: =BETA!Q9 -> -0.014874362 | E9: Standard Error | F9: 0.015617485
B10: =BETA!P10 -> -0.011845028 | C10: =BETA!Q10 -> -0.0021838216 | E10: Observations | F10: 1922
B11: =BETA!P11 -> -0.0019607263 | C11: =BETA!Q11 -> -0.0064845504
B12: =BETA!P12 -> -0.015137786 | C12: =BETA!Q12 -> -0.010676258 | E12: ANOVA
B13: =BETA!P13 -> -0.0046086923 | C13: =BETA!Q13 -> -0.023431502 | F13: df | G13: SS | H13: MS | I13: F | J13: Significance F
B14: =BETA!P14 -> 0.0027167852 | C14: =BETA!Q14 -> 0.00098941336 | E14: Regression | F14: 1 | G14: 0.41826327 | H14: 0.41826327 | I14: 1714.8556 | J14: 2.1116358e-268
B15: =BETA!P15 -> 0.00097966633 | C15: =BETA!Q15 -> 0.014188814 | E15: Residual | F15: 1920 | G15: 0.46829919 | H15: 0.00024390583
B16: =BETA!P16 -> 0.00017339384 | C16: =BETA!Q16 -> 0.0098957878 | E16: Total | F16: 1921 | G16: 0.88656246
B17: =BETA!P17 -> 0.0029291135 | C17: =BETA!Q17 -> 0.0017361953
B18: =BETA!P18 -> 0.00010102731 | C18: =BETA!Q18 -> -0.0034270578 | F18: Coefficients | G18: Standard Error | H18: t Stat | I18: P-value | J18: Lower 95% | K18: Upper 95% | L18: Lower 95.0% | M18: Upper 95.0% | N18: Upper 95.0%
B19: =BETA!P19 -> -0.008237484 | C19: =BETA!Q19 -> -0.01918489 | E19: Intercept | F19: 0.00024588418 | G19: 0.00035655947 | H19: 0.68960215 | I19: 0.49052775 | J19: -0.00045340036 | K19: 0.00094516871 | L19: -0.00045340036 | M19: 0.00094516871 | N19: 0.00094516871
B20: =BETA!P20 -> -0.010091405 | C20: =BETA!Q20 -> -0.012548212 | E20: X Variable 1 | F20: 1.3492188 | G20: 0.032581314 | H20: 41.410814 | I20: 2.1116358e-268 | J20: 1.2853203 | K20: 1.4131172 | L20: 1.2853203 | M20: 1.4131172 | N20: 1.4131172
B21: =BETA!P21 -> 0.0013145226 | C21: =BETA!Q21 -> 0.0054254631
B22: =BETA!P22 -> 0.0015334554 | C22: =BETA!Q22 -> 0.0082064926
B23: =BETA!P23 -> 0.019137651 | C23: =BETA!Q23 -> 0.0011317506 | F23: Beta
B24: =BETA!P24 -> -0.00013819028 | C24: =BETA!Q24 -> -0.0075032438
B25: =BETA!P25 -> -0.0019819333 | C25: =BETA!Q25 -> 0.00094099009
B26: =BETA!P26 -> 0.011440011 | C26: =BETA!Q26 -> -0.0010896484 | F26: VAR
B27: =BETA!P27 -> 0.0056260775 | C27: =BETA!Q27 -> 0.0081435684 | F27: Mean | G27: =AVERAGE(C3:C1924) -> -0.00038562356
B28: =BETA!P28 -> 0.0026796761 | C28: =BETA!Q28 -> -0.0057676825 | F28: STD dev | G28: =_xlfn.STDEV.S(C3:C1924) -> 0.021482805
B29: =BETA!P29 -> 0.00037141251 | C29: =BETA!Q29 -> -0.01715325 | F29: Alpha | G29: 0.05
B30: =BETA!P30 -> 0.00038785439 | C30: =BETA!Q30 -> -0.0012077904 | F30: Z score | G30: =_xlfn.NORM.S.INV(G29) -> -1.6448536
B31: =BETA!P31 -> -0.00075887184 | C31: =BETA!Q31 -> 0.0045718385 | F31: VaR | G31: =G27+(G28*G30) -> -0.035721693
B32: =BETA!P32 -> 0.0026270714 | C32: =BETA!Q32 -> 0.010669693
B33: =BETA!P33 -> 0.00042163994 | C33: =BETA!Q33 -> -0.0012902587
B34: =BETA!P34 -> 0.0016071923 | C34: =BETA!Q34 -> 0.00049645039
B35: =BETA!P35 -> 0.013257541 | C35: =BETA!Q35 -> 0.0043087504 | F35: Annualised VAR
B36: =BETA!P36 -> 0.0070681865 | C36: =BETA!Q36 -> 0.012132673 | F36: assume trading days | G36: 252
B37: =BETA!P37 -> 0.0025394074 | C37: =BETA!Q37 -> -0.0033255117 | F37: Mean | G37: =AVERAGE(C3:C1924)*G36 -> -0.097177137
B38: =BETA!P38 -> 0.0027265515 | C38: =BETA!Q38 -> -0.007276335 | F38: STD dev | G38: =_xlfn.STDEV.S(C3:C1924)*SQRT(G36) -> 0.34102896
B39: =BETA!P39 -> 0.0039849572 | C39: =BETA!Q39 -> 0.0019718039 | F39: Alpha | G39: 0.05
B40: =BETA!P40 -> -0.017938018 | C40: =BETA!Q40 -> -0.025840716 | F40: Z score | G40: =_xlfn.NORM.S.INV(G39) -> -1.6448536
B41: =BETA!P41 -> 0.004127156 | C41: =BETA!Q41 -> 0.0088048668 | F41: VaR | G41: =G37+(G38*G40) -> -0.65811985
...

Sheet Regression-ICICI
B1: Sensex Log return | C1: ICICI Bank Log returns
B3: =BETA!P3 -> 0.018123739 | C3: =BETA!R3 -> 0.022424818 | E3: SUMMARY OUTPUT
B4: =BETA!P4 -> 0.0024707577 | C4: =BETA!R4 -> -0.008715139
B5: =BETA!P5 -> -0.0041051111 | C5: =BETA!R5 -> -0.00056126173 | E5: Regression Statistics
B6: =BETA!P6 -> 0.0093840135 | C6: =BETA!R6 -> 0.0058217809 | E6: Multiple R | F6: 0.73981936
B7: =BETA!P7 -> -0.0004206368 | C7: =BETA!R7 -> 0.010696477 | E7: R Square | F7: 0.54733268
B8: =BETA!P8 -> -0.013931025 | C8: =BETA!R8 -> -0.011143105 | E8: Adjusted R Square | F8: 0.54709692
B9: =BETA!P9 -> -0.0072749034 | C9: =BETA!R9 -> -0.016061588 | E9: Standard Error | F9: 0.013023808
B10: =BETA!P10 -> -0.011845028 | C10: =BETA!R10 -> -0.0065280329 | E10: Observations | F10: 1922
B11: =BETA!P11 -> -0.0019607263 | C11: =BETA!R11 -> -0.002478127
B12: =BETA!P12 -> -0.015137786 | C12: =BETA!R12 -> -0.031683438 | E12: ANOVA
B13: =BETA!P13 -> -0.0046086923 | C13: =BETA!R13 -> -0.015045638 | F13: df | G13: SS | H13: MS | I13: F | J13: Significance F
B14: =BETA!P14 -> 0.0027167852 | C14: =BETA!R14 -> -0.0048917499 | E14: Regression | F14: 1 | G14: 0.3937762 | H14: 0.3937762 | I14: 2321.5256 | J14: 0
B15: =BETA!P15 -> 0.00097966633 | C15: =BETA!R15 -> 0.0011649629 | E15: Residual | F15: 1920 | G15: 0.3256696 | H15: 0.00016961958
B16: =BETA!P16 -> 0.00017339384 | C16: =BETA!R16 -> -0.024836151 | E16: Total | F16: 1921 | G16: 0.71944581
B17: =BETA!P17 -> 0.0029291135 | C17: =BETA!R17 -> -0.00024697456
B18: =BETA!P18 -> 0.00010102731 | C18: =BETA!R18 -> 0.0028775815 | F18: Coefficients | G18: Standard Error | H18: t Stat | I18: P-value | J18: Lower 95% | K18: Upper 95% | L18: Lower 95.0% | M18: Upper 95.0%
B19: =BETA!P19 -> -0.008237484 | C19: =BETA!R19 -> -0.0019311768 | E19: Intercept | F19: -0.00017488111 | G19: 0.0002973438 | H19: -0.58814448 | I19: 0.55650449 | J19: -0.00075803186 | K19: 0.00040826963 | L19: -0.00075803186 | M19: 0.00040826963
B20: =BETA!P20 -> -0.010091405 | C20: =BETA!R20 -> -0.0043691591 | E20: X Variable 1 | F20: 1.3091284 | G20: 0.027170367 | H20: 48.182212 | I20: 0 | J20: 1.2558419 | K20: 1.3624149 | L20: 1.2558419 | M20: 1.3624149
B21: =BETA!P21 -> 0.0013145226 | C21: =BETA!R21 -> -0.0034759615
B22: =BETA!P22 -> 0.0015334554 | C22: =BETA!R22 -> -0.0017425221
B23: =BETA!P23 -> 0.019137651 | C23: =BETA!R23 -> 0.015124642 | F23: Beta
B24: =BETA!P24 -> -0.00013819028 | C24: =BETA!R24 -> 0.0013896839
B25: =BETA!P25 -> -0.0019819333 | C25: =BETA!R25 -> -0.0047492413
B26: =BETA!P26 -> 0.011440011 | C26: =BETA!R26 -> 0.011912188
B27: =BETA!P27 -> 0.0056260775 | C27: =BETA!R27 -> 0.013693879 | E27: VAR
B28: =BETA!P28 -> 0.0026796761 | C28: =BETA!R28 -> 0.0093168376 | F28: Mean | G28: =AVERAGE(C3:C1924) -> -0.00078762438
B29: =BETA!P29 -> 0.00037141251 | C29: =BETA!R29 -> -0.014852351 | F29: STD dev | G29: =_xlfn.STDEV.S(C3:C1924) -> 0.019352424
B30: =BETA!P30 -> 0.00038785439 | C30: =BETA!R30 -> 0.0064950914 | F30: Alpha | G30: 0.05
B31: =BETA!P31 -> -0.00075887184 | C31: =BETA!R31 -> 0.0071279545 | F31: Z score | G31: =_xlfn.NORM.S.INV(G30) -> -1.6448536
B32: =BETA!P32 -> 0.0026270714 | C32: =BETA!R32 -> -0.008927919 | F32: VaR | G32: =G28+(G29*G31) -> -0.032619528
B33: =BETA!P33 -> 0.00042163994 | C33: =BETA!R33 -> 0.0023193516
B34: =BETA!P34 -> 0.0016071923 | C34: =BETA!R34 -> 0.00075861935
B35: =BETA!P35 -> 0.013257541 | C35: =BETA!R35 -> 0.0078319521 | E35: Annualised VAR
B36: =BETA!P36 -> 0.0070681865 | C36: =BETA!R36 -> -0.004524715 | F36: assume trading days | H36: 252
B37: =BETA!P37 -> 0.0025394074 | C37: =BETA!R37 -> 0.012256509 | F37: Mean | H37: =AVERAGE(C3:C1924)*H36 -> -0.19848134
B38: =BETA!P38 -> 0.0027265515 | C38: =BETA!R38 -> -0.0037006459 | F38: STD dev | H38: =_xlfn.STDEV.S(C3:C1924)*SQRT(H36) -> 0.3072102
B39: =BETA!P39 -> 0.0039849572 | C39: =BETA!R39 -> 0.00039433732 | F39: Alpha | H39: 0.05
B40: =BETA!P40 -> -0.017938018 | C40: =BETA!R40 -> -0.012057896 | F40: Z score | H40: =_xlfn.NORM.S.INV(H39) -> -1.6448536
B41: =BETA!P41 -> 0.004127156 | C41: =BETA!R41 -> 0.0020330477 | F41: VaR | H41: =H37+(H38*H40) -> -0.70379715
...

Sheet Regression-IDFC
B1: Sensex Log return | C1: IDFC Bank Log returns
B3: =BETA!P3 -> 0.018123739 | C3: =BETA!S3 -> -0.039423637 | E3: SUMMARY OUTPUT
B4: =BETA!P4 -> 0.0024707577 | C4: =BETA!S4 -> 0.035392434
B5: =BETA!P5 -> -0.0041051111 | C5: =BETA!S5 -> 0.001053186 | E5: Regression Statistics
B6: =BETA!P6 -> 0.0093840135 | C6: =BETA!S6 -> 0.0061215757 | E6: Multiple R | F6: 0.5562363
B7: =BETA!P7 -> -0.0004206368 | C7: =BETA!S7 -> 0.0093718145 | E7: R Square | F7: 0.30939882
B8: =BETA!P8 -> -0.013931025 | C8: =BETA!S8 -> -0.028027759 | E8: Adjusted R Square | F8: 0.30903913
B9: =BETA!P9 -> -0.0072749034 | C9: =BETA!S9 -> -0.010357235 | E9: Standard Error | F9: 0.02013411
B10: =BETA!P10 -> -0.011845028 | C10: =BETA!S10 -> -0.0052191246 | E10: Observations | F10: 1922
B11: =BETA!P11 -> -0.0019607263 | C11: =BETA!S11 -> -0.014540423
B12: =BETA!P12 -> -0.015137786 | C12: =BETA!S12 -> -0.032185831 | E12: ANOVA
B13: =BETA!P13 -> -0.0046086923 | C13: =BETA!S13 -> 0.011093467 | F13: df | G13: SS | H13: MS | I13: F | J13: Significance F
B14: =BETA!P14 -> 0.0027167852 | C14: =BETA!S14 -> 0.02127543 | E14: Regression | F14: 1 | G14: 0.3487044 | H14: 0.3487044 | I14: 860.18638 | J14: 1.4883153e-156
B15: =BETA!P15 -> 0.00097966633 | C15: =BETA!S15 -> 0.013274129 | E15: Residual | F15: 1920 | G15: 0.77833417 | H15: 0.00040538238
B16: =BETA!P16 -> 0.00017339384 | C16: =BETA!S16 -> 0.018079791 | E16: Total | F16: 1921 | G16: 1.1270386
B17: =BETA!P17 -> 0.0029291135 | C17: =BETA!S17 -> 0.017061358
B18: =BETA!P18 -> 0.00010102731 | C18: =BETA!S18 -> 0.0074711493 | F18: Coefficients | G18: Standard Error | H18: t Stat | I18: P-value | J18: Lower 95% | K18: Upper 95% | L18: Lower 95.0% | M18: Upper 95.0%
B19: =BETA!P19 -> -0.008237484 | C19: =BETA!S19 -> 0.00311096 | E19: Intercept | F19: 0.00055363151 | G19: 0.00045967757 | H19: 1.2043909 | I19: 0.22858695 | J19: -0.00034788829 | K19: 0.0014551513 | L19: -0.00034788829 | M19: 0.0014551513
B20: =BETA!P20 -> -0.010091405 | C20: =BETA!S20 -> -0.019516214 | E20: X Variable 1 | F20: 1.2319305 | G20: 0.042003932 | H20: 29.328934 | I20: 1.4883153e-156 | J20: 1.1495524 | K20: 1.3143087 | L20: 1.1495524 | M20: 1.3143087
B21: =BETA!P21 -> 0.0013145226 | C21: =BETA!S21 -> 0.015019493
B22: =BETA!P22 -> 0.0015334554 | C22: =BETA!S22 -> 0.012060794
B23: =BETA!P23 -> 0.019137651 | C23: =BETA!S23 -> 0.01411468 | F23: Beta
B24: =BETA!P24 -> -0.00013819028 | C24: =BETA!S24 -> -0.0069474142
B25: =BETA!P25 -> -0.0019819333 | C25: =BETA!S25 -> 0.018364597
B26: =BETA!P26 -> 0.011440011 | C26: =BETA!S26 -> 0.012113315
B27: =BETA!P27 -> 0.0056260775 | C27: =BETA!S27 -> 0.011968337
B28: =BETA!P28 -> 0.0026796761 | C28: =BETA!S28 -> -0.022580275 | G28: VAR
B29: =BETA!P29 -> 0.00037141251 | C29: =BETA!S29 -> -0.0078654911 | G29: Mean | H29: =AVERAGE(C3:C1924) -> -2.2978968e-05
B30: =BETA!P30 -> 0.00038785439 | C30: =BETA!S30 -> 0.032724784 | G30: STD dev | H30: =_xlfn.STDEV.S(C3:C1924) -> 0.024221761
B31: =BETA!P31 -> -0.00075887184 | C31: =BETA!S31 -> -0.014742282 | G31: Alpha | H31: 0.05
B32: =BETA!P32 -> 0.0026270714 | C32: =BETA!S32 -> 0.014579667 | G32: Z score | H32: =_xlfn.NORM.S.INV(H31) -> -1.6448536
B33: =BETA!P33 -> 0.00042163994 | C33: =BETA!S33 -> 0.010837146 | G33: VaR | H33: =H29+(H30*H32) -> -0.03986423
B34: =BETA!P34 -> 0.0016071923 | C34: =BETA!S34 -> -0.0084006956
B35: =BETA!P35 -> 0.013257541 | C35: =BETA!S35 -> 0.020394123
B36: =BETA!P36 -> 0.0070681865 | C36: =BETA!S36 -> 0.018583212 | G36: Annualised VAR
B37: =BETA!P37 -> 0.0025394074 | C37: =BETA!S37 -> -0.0056329362 | G37: assume trading days | I37: 252
B38: =BETA!P38 -> 0.0027265515 | C38: =BETA!S38 -> -0.0062962588 | G38: Mean | I38: =AVERAGE(C3:C1924)*I37 -> -0.0057906999
B39: =BETA!P39 -> 0.0039849572 | C39: =BETA!S39 -> -0.019291152 | G39: STD dev | I39: =_xlfn.STDEV.S(C3:C1924)*SQRT(I37) -> 0.38450853
B40: =BETA!P40 -> -0.017938018 | C40: =BETA!S40 -> 0.0022511667 | G40: Alpha | I40: 0.05
B41: =BETA!P41 -> 0.004127156 | C41: =BETA!S41 -> -0.0049915569 | G41: Z score | I41: =_xlfn.NORM.S.INV(I40) -> -1.6448536
...

Sheet Regression-AU Small
B1: Sensex Log return | C1: AU small finance Log returns
B3: =BETA!P3 -> 0.018123739 | C3: =BETA!T3 -> 0.0088304942 | E3: SUMMARY OUTPUT
B4: =BETA!P4 -> 0.0024707577 | C4: =BETA!T4 -> 0.036367644
B5: =BETA!P5 -> -0.0041051111 | C5: =BETA!T5 -> 0.034307313 | E5: Regression Statistics
B6: =BETA!P6 -> 0.0093840135 | C6: =BETA!T6 -> -0.028014027 | E6: Multiple R | F6: 0.38756394
B7: =BETA!P7 -> -0.0004206368 | C7: =BETA!T7 -> -0.014170552 | E7: R Square | F7: 0.15020581
B8: =BETA!P8 -> -0.013931025 | C8: =BETA!T8 -> -0.013268255 | E8: Adjusted R Square | F8: 0.14976321
B9: =BETA!P9 -> -0.0072749034 | C9: =BETA!T9 -> -0.032866588 | E9: Standard Error | F9: 0.022610946
B10: =BETA!P10 -> -0.011845028 | C10: =BETA!T10 -> 0.0010465726 | E10: Observations | F10: 1922
B11: =BETA!P11 -> -0.0019607263 | C11: =BETA!T11 -> -0.042344644
B12: =BETA!P12 -> -0.015137786 | C12: =BETA!T12 -> -0.024504138 | E12: ANOVA
B13: =BETA!P13 -> -0.0046086923 | C13: =BETA!T13 -> 0.022219785 | F13: df | G13: SS | H13: MS | I13: F | J13: Significance F
B14: =BETA!P14 -> 0.0027167852 | C14: =BETA!T14 -> 0.0086134882 | E14: Regression | F14: 1 | G14: 0.17350487 | H14: 0.17350487 | I14: 339.37059 | J14: 6.4837814e-70
B15: =BETA!P15 -> 0.00097966633 | C15: =BETA!T15 -> 0.028953737 | E15: Residual | F15: 1920 | G15: 0.98160939 | H15: 0.00051125489
B16: =BETA!P16 -> 0.00017339384 | C16: =BETA!T16 -> 0.031578099 | E16: Total | F16: 1921 | G16: 1.1551143
B17: =BETA!P17 -> 0.0029291135 | C17: =BETA!T17 -> 0.010063326
B18: =BETA!P18 -> 0.00010102731 | C18: =BETA!T18 -> 0.016219034 | F18: Coefficients | G18: Standard Error | H18: t Stat | I18: P-value | J18: Lower 95% | K18: Upper 95% | L18: Lower 95.0% | M18: Upper 95.0%
B19: =BETA!P19 -> -0.008237484 | C19: =BETA!T19 -> -0.012276788 | E19: Intercept | F19: 5.7515226e-05 | G19: 0.0005162257 | H19: 0.11141488 | I19: 0.911299 | J19: -0.00095490677 | K19: 0.0010699372 | L19: -0.00095490677 | M19: 0.0010699372
B20: =BETA!P20 -> -0.010091405 | C20: =BETA!T20 -> 0.0034709571 | E20: X Variable 1 | F20: 0.86898713 | G20: 0.047171126 | H20: 18.422014 | I20: 6.4837814e-70 | J20: 0.7764751 | K20: 0.96149916 | L20: 0.7764751 | M20: 0.96149916
B21: =BETA!P21 -> 0.0013145226 | C21: =BETA!T21 -> 0.01672809
B22: =BETA!P22 -> 0.0015334554 | C22: =BETA!T22 -> 0.014422043
B23: =BETA!P23 -> 0.019137651 | C23: =BETA!T23 -> -0.016037407 | F23: Beta
B24: =BETA!P24 -> -0.00013819028 | C24: =BETA!T24 -> -0.060057825
B25: =BETA!P25 -> -0.0019819333 | C25: =BETA!T25 -> 0.016552754
B26: =BETA!P26 -> 0.011440011 | C26: =BETA!T26 -> 0.008593365 | G26: VAR
B27: =BETA!P27 -> 0.0056260775 | C27: =BETA!T27 -> -0.0047545887 | G27: Mean | H27: =AVERAGE(C3:C1924) -> -0.000349218
B28: =BETA!P28 -> 0.0026796761 | C28: =BETA!T28 -> -0.017724608 | G28: STD dev | H28: =_xlfn.STDEV.S(C3:C1924) -> 0.024521599
B29: =BETA!P29 -> 0.00037141251 | C29: =BETA!T29 -> -0.045238977 | G29: Alpha | H29: 0.05
B30: =BETA!P30 -> 0.00038785439 | C30: =BETA!T30 -> 0.038366754 | G30: Z score | H30: =_xlfn.NORM.S.INV(H29) -> -1.6448536
B31: =BETA!P31 -> -0.00075887184 | C31: =BETA!T31 -> 0.024316445 | G31: VaR | H31: =H27+(H28*H30) -> -0.040683659
B32: =BETA!P32 -> 0.0026270714 | C32: =BETA!T32 -> 0.0333686
B33: =BETA!P33 -> 0.00042163994 | C33: =BETA!T33 -> 0.0024380345
B34: =BETA!P34 -> 0.0016071923 | C34: =BETA!T34 -> 0.02897723 | G34: Annualised VAR
B35: =BETA!P35 -> 0.013257541 | C35: =BETA!T35 -> 0.015733299 | G35: assume trading days | I35: 252
B36: =BETA!P36 -> 0.0070681865 | C36: =BETA!T36 -> 0.021078563 | G36: Mean | I36: =AVERAGE(C3:C1924)*I35 -> -0.088002935
B37: =BETA!P37 -> 0.0025394074 | C37: =BETA!T37 -> -0.0099292198 | G37: STD dev | I37: =_xlfn.STDEV.S(C3:C1924)*SQRT(I35) -> 0.38926832
B38: =BETA!P38 -> 0.0027265515 | C38: =BETA!T38 -> 0.015822981 | G38: Alpha | I38: 0.05
B39: =BETA!P39 -> 0.0039849572 | C39: =BETA!T39 -> 0.0071103232 | G39: Z score | I39: =_xlfn.NORM.S.INV(I38) -> -1.6448536
B40: =BETA!P40 -> -0.017938018 | C40: =BETA!T40 -> 0.014974427 | G40: VaR | I40: =I36+(I37*I39) -> -0.72829234
B41: =BETA!P41 -> 0.004127156 | C41: =BETA!T41 -> -0.012975925
...

Sheet Regression-SBI
B1: Sensex Log return | C1: SBI Log retuns
B3: =BETA!P3 -> 0.018123739 | C3: =BETA!U3 -> -0.00025920166 | E3: SUMMARY OUTPUT
B4: =BETA!P4 -> 0.0024707577 | C4: =BETA!U4 -> 0.0010364038
B5: =BETA!P5 -> -0.0041051111 | C5: =BETA!U5 -> -0.010805286 | E5: Regression Statistics
B6: =BETA!P6 -> 0.0093840135 | C6: =BETA!U6 -> 0.011517191 | E6: Multiple R | F6: 0.66242096
B7: =BETA!P7 -> -0.0004206368 | C7: =BETA!U7 -> 0.010234055 | E7: R Square | F7: 0.43880153
B8: =BETA!P8 -> -0.013931025 | C8: =BETA!U8 -> -0.035988238 | E8: Adjusted R Square | F8: 0.43850924
B9: =BETA!P9 -> -0.0072749034 | C9: =BETA!U9 -> -0.0048577703 | E9: Standard Error | F9: 0.015825475
B10: =BETA!P10 -> -0.011845028 | C10: =BETA!U10 -> -0.0059545889 | E10: Observations | F10: 1922
B11: =BETA!P11 -> -0.0019607263 | C11: =BETA!U11 -> -0.011337684
B12: =BETA!P12 -> -0.015137786 | C12: =BETA!U12 -> -0.018564084 | E12: ANOVA
B13: =BETA!P13 -> -0.0046086923 | C13: =BETA!U13 -> 0.0064783135 | F13: df | G13: SS | H13: MS | I13: F | J13: Significance F
B14: =BETA!P14 -> 0.0027167852 | C14: =BETA!U14 -> -0.0066166069 | E14: Regression | F14: 1 | G14: 0.37598144 | H14: 0.37598144 | I14: 1501.2495 | J14: 3.8961055e-243
B15: =BETA!P15 -> 0.00097966633 | C15: =BETA!U15 -> 0.0093606575 | E15: Residual | F15: 1920 | G15: 0.48085568 | H15: 0.00025044567
B16: =BETA!P16 -> 0.00017339384 | C16: =BETA!U16 -> -0.0013024852 | E16: Total | F16: 1921 | G16: 0.85683712
B17: =BETA!P17 -> 0.0029291135 | C17: =BETA!U17 -> 0.0052680312
B18: =BETA!P18 -> 0.00010102731 | C18: =BETA!U18 -> -0.00095576195 | F18: Coefficients | G18: Standard Error | H18: t Stat | I18: P-value | J18: Lower 95% | K18: Upper 95% | L18: Lower 95.0% | M18: Upper 95.0%
B19: =BETA!P19 -> -0.008237484 | C19: =BETA!U19 -> -0.0023249463 | E19: Intercept | F19: 5.9328299e-05 | G19: 0.00036130806 | H19: 0.1642042 | I19: 0.86958768 | J19: -0.00064926917 | K19: 0.00076792577 | L19: -0.00064926917 | M19: 0.00076792577
B20: =BETA!P20 -> -0.010091405 | C20: =BETA!U20 -> -0.019773874 | E20: X Variable 1 | F20: 1.2792067 | G20: 0.033015226 | H20: 38.745961 | I20: 3.8961055e-243 | J20: 1.2144572 | K20: 1.3439561 | L20: 1.2144572 | M20: 1.3439561
B21: =BETA!P21 -> 0.0013145226 | C21: =BETA!U21 -> -0.02940659
B22: =BETA!P22 -> 0.0015334554 | C22: =BETA!U22 -> -0.009392454
B23: =BETA!P23 -> 0.019137651 | C23: =BETA!U23 -> 0.021685348 | F23: Beta
B24: =BETA!P24 -> -0.00013819028 | C24: =BETA!U24 -> 0.0098954723
B25: =BETA!P25 -> -0.0019819333 | C25: =BETA!U25 -> 0.0077068973
B26: =BETA!P26 -> 0.011440011 | C26: =BETA!U26 -> 0.0077864687 | G26: VAR
B27: =BETA!P27 -> 0.0056260775 | C27: =BETA!U27 -> 0.010608352 | G27: Mean | H27: =AVERAGE(C3:C1924) -> -0.00053940997
B28: =BETA!P28 -> 0.0026796761 | C28: =BETA!U28 -> -0.0032944436 | G28: STD dev | H28: =_xlfn.STDEV.S(C3:C1924) -> 0.021119589
B29: =BETA!P29 -> 0.00037141251 | C29: =BETA!U29 -> -0.0020645524 | G29: Alpha | H29: 0.05
B30: =BETA!P30 -> 0.00038785439 | C30: =BETA!U30 -> 0.0026143806 | G30: Z score | H30: =_xlfn.NORM.S.INV(H29) -> -1.6448536
B31: =BETA!P31 -> -0.00075887184 | C31: =BETA!U31 -> -0.0076560018 | G31: VaR | H31: =H27+(H28*H30) -> -0.035278042
B32: =BETA!P32 -> 0.0026270714 | C32: =BETA!U32 -> 0.0075872898
B33: =BETA!P33 -> 0.00042163994 | C33: =BETA!U33 -> 0.0075301561
B34: =BETA!P34 -> 0.0016071923 | C34: =BETA!U34 -> -0.0028000701 | G34: Annualised VAR
B35: =BETA!P35 -> 0.013257541 | C35: =BETA!U35 -> 0.0077662356 | G35: assume trading days | I35: 252
B36: =BETA!P36 -> 0.0070681865 | C36: =BETA!U36 -> 0.00054274085 | G36: Mean | I36: =AVERAGE(C3:C1924)*I35 -> -0.13593131
B37: =BETA!P37 -> 0.0025394074 | C37: =BETA!U37 -> 0.02020949 | G37: STD dev | I37: =_xlfn.STDEV.S(C3:C1924)*SQRT(I35) -> 0.33526308
B38: =BETA!P38 -> 0.0027265515 | C38: =BETA!U38 -> 0.018178726 | G38: Alpha | I38: 0.05
B39: =BETA!P39 -> 0.0039849572 | C39: =BETA!U39 -> 0.017020311 | G39: Z score | I39: =_xlfn.NORM.S.INV(I38) -> -1.6448536
B40: =BETA!P40 -> -0.017938018 | C40: =BETA!U40 -> -0.0237001 | G40: VaR | I40: =I36+(I37*I39) -> -0.68739
B41: =BETA!P41 -> 0.004127156 | C41: =BETA!U41 -> 0.0066145171
...

Sheet Regression-Bank of Baroda
B1: Sensex Log return | C1: Bank of Baroda Log returns
B3: =BETA!P3 -> 0.018123739 | C3: =BETA!V3 -> -0.00021876572 | E3: SUMMARY OUTPUT
B4: =BETA!P4 -> 0.0024707577 | C4: =BETA!V4 -> 0.010663634
B5: =BETA!P5 -> -0.0041051111 | C5: =BETA!V5 -> -0.047159319 | E5: Regression Statistics
B6: =BETA!P6 -> 0.0093840135 | C6: =BETA!V6 -> 0.012313816 | E6: Multiple R | F6: 0.52281835
B7: =BETA!P7 -> -0.0004206368 | C7: =BETA!V7 -> 0.0062564444 | E7: R Square | F7: 0.27333903
B8: =BETA!P8 -> -0.013931025 | C8: =BETA!V8 -> -0.035228159 | E8: Adjusted R Square | F8: 0.27296056
B9: =BETA!P9 -> -0.0072749034 | C9: =BETA!V9 -> -0.0048571854 | E9: Standard Error | F9: 0.022663322
B10: =BETA!P10 -> -0.011845028 | C10: =BETA!V10 -> -0.0088028327 | E10: Observations | F10: 1922
B11: =BETA!P11 -> -0.0019607263 | C11: =BETA!V11 -> -0.020894166
B12: =BETA!P12 -> -0.015137786 | C12: =BETA!V12 -> -0.017346489 | E12: ANOVA
B13: =BETA!P13 -> -0.0046086923 | C13: =BETA!V13 -> -0.0010698829 | F13: df | G13: SS | H13: MS | I13: F | J13: Significance F
B14: =BETA!P14 -> 0.0027167852 | C14: =BETA!V14 -> -0.015297415 | E14: Regression | F14: 1 | G14: 0.37095239 | H14: 0.37095239 | I14: 722.22255 | J14: 2.6293284e-135
B15: =BETA!P15 -> 0.00097966633 | C15: =BETA!V15 -> 0.00079020154 | E15: Residual | F15: 1920 | G15: 0.98616222 | H15: 0.00051362616
B16: =BETA!P16 -> 0.00017339384 | C16: =BETA!V16 -> 0.0072309029 | E16: Total | F16: 1921 | G16: 1.3571146
B17: =BETA!P17 -> 0.0029291135 | C17: =BETA!V17 -> 0.0091235722
B18: =BETA!P18 -> 0.00010102731 | C18: =BETA!V18 -> 0.0061008275 | F18: Coefficients | G18: Standard Error | H18: t Stat | I18: P-value | J18: Lower 95% | K18: Upper 95% | L18: Lower 95.0% | M18: Upper 95.0%
B19: =BETA!P19 -> -0.008237484 | C19: =BETA!V19 -> -0.0094088671 | E19: Intercept | F19: 0.00041446411 | G19: 0.00051742147 | H19: 0.80101838 | I19: 0.42322012 | J19: -0.00060030304 | K19: 0.0014292313 | L19: -0.00060030304 | M19: 0.0014292313
B20: =BETA!P20 -> -0.010091405 | C20: =BETA!V20 -> -0.046376162 | E20: X Variable 1 | F20: 1.2706227 | G20: 0.047280393 | H20: 26.874199 | I20: 2.6293284e-135 | J20: 1.1778963 | K20: 1.363349 | L20: 1.1778963 | M20: 1.363349
B21: =BETA!P21 -> 0.0013145226 | C21: =BETA!V21 -> -5.1042544e-05
B22: =BETA!P22 -> 0.0015334554 | C22: =BETA!V22 -> 0.0059036255
B23: =BETA!P23 -> 0.019137651 | C23: =BETA!V23 -> 0.03053329 | F23: Beta
B24: =BETA!P24 -> -0.00013819028 | C24: =BETA!V24 -> 0.0077951124
B25: =BETA!P25 -> -0.0019819333 | C25: =BETA!V25 -> 0.01867495
B26: =BETA!P26 -> 0.011440011 | C26: =BETA!V26 -> 0.007830071 | G26: VAR
B27: =BETA!P27 -> 0.0056260775 | C27: =BETA!V27 -> 0.015572229 | G27: Mean | H27: =AVERAGE(C3:C1924) -> -0.00018025638
B28: =BETA!P28 -> 0.0026796761 | C28: =BETA!V28 -> -0.02215685 | G28: STD dev | H28: =_xlfn.STDEV.S(C3:C1924) -> 0.026579364
B29: =BETA!P29 -> 0.00037141251 | C29: =BETA!V29 -> -0.013494831 | G29: Alpha | H29: 0.05
B30: =BETA!P30 -> 0.00038785439 | C30: =BETA!V30 -> 0.0042125713 | G30: Z score | H30: =_xlfn.NORM.S.INV(H29) -> -1.6448536
B31: =BETA!P31 -> -0.00075887184 | C31: =BETA!V31 -> -0.0087353754 | G31: VaR | H31: =H27+(H28*H30) -> -0.043899419
B32: =BETA!P32 -> 0.0026270714 | C32: =BETA!V32 -> 0.027119654
B33: =BETA!P33 -> 0.00042163994 | C33: =BETA!V33 -> 0.0082203893
B34: =BETA!P34 -> 0.0016071923 | C34: =BETA!V34 -> -0.0083152704
B35: =BETA!P35 -> 0.013257541 | C35: =BETA!V35 -> 0.020892288 | G35: Annualised VAR
B36: =BETA!P36 -> 0.0070681865 | C36: =BETA!V36 -> 0.0050515691 | G36: assume trading days | I36: 252
B37: =BETA!P37 -> 0.0025394074 | C37: =BETA!V37 -> 0.015549702 | G37: Mean | I37: =AVERAGE(C3:C1924)*I36 -> -0.045424607
B38: =BETA!P38 -> 0.0027265515 | C38: =BETA!V38 -> 0.0014099563 | G38: STD dev | I38: =_xlfn.STDEV.S(C3:C1924)*SQRT(I36) -> 0.42193432
B39: =BETA!P39 -> 0.0039849572 | C39: =BETA!V39 -> -0.032942851 | G39: Alpha | I39: 0.05
B40: =BETA!P40 -> -0.017938018 | C40: =BETA!V40 -> -0.023285599 | G40: Z score | I40: =_xlfn.NORM.S.INV(I39) -> -1.6448536
B41: =BETA!P41 -> 0.004127156 | C41: =BETA!V41 -> 0.01360955 | G41: VaR | I41: =I37+(I38*I40) -> -0.7394448
...

Sheet Credit Assessment
B1: Bank Name | C1: Year | D1: Gross NPA % | E1: Net NPA % | F1: PCR % | G1: GNPA (₹ Cr) | H1: NNPA (₹ Cr) | I1: Provisions (₹ Cr) | J1: Advances (₹ Cr) | K1: Accretions (₹ Cr) | L1: Write offs other than those under technical/prudential Write offs of gross NPAs | M1: Technical/Prudential Write offs of gross NPAs | N1: Total Write Offs | O1: Upgradations of Gross NPAs | P1: Recoveries (excluding recoveries made from upgraded accounts) of gross NPAs | Q1: Total Recoveries & Upgradations | R1: Slippage Ratio (Accretions to Advances) | S1: Recoveries & Upgradations to GNPA % | T1: WriteOffs to GNPA% | U1: Upgradations to GNPA % | V1: Recoveries to GNPA % | W1: GNPA to Advances% | X1: Write Off to Advances % | Y1: Recoveries to Advances %
B2: Axis Bank Ltd. | C2: 2016 | D2: 1.75 | E2: 0.7 | F2: 72.27 | G2: 6087.51 | H2: 2522.14 | I2: 12205.72 | J2: 373069.35 | K2: 2895.59 | L2: 1788.52 | M2: 1534.01 | N2: =L2+M2 -> 3322.53 | O2: 341.87 | P2: 1702.84 | Q2: =O2+P2 -> 2044.71 | R2: =K2/J2 -> 0.0077615328 | S2: =Q2/G2 -> 0.3358861 | T2: =N2/G2 -> 0.54579459 | U2: =O2/G2 -> 0.056159251 | V2: =P2/G2 -> 0.27972685 | W2: =G2/J2 -> 0.016317368 | X2: =N2/J2 -> 0.0089059313 | Y2: =P2/J2 -> 0.0045644061
C3: 2017 | D3: 5.04 | E3: 2.11 | F3: 64.79 | G3: 21280.48 | H3: 8626.55 | I3: 17355.95 | J3: 439650.31 | K3: 10583.44 | L3: 1718.08 | M3: 504.01 | N3: =L3+M3 -> 2222.09 | O3: 2365.78 | P3: 2000.95 | Q3: =O3+P3 -> 4366.73 | R3: =K3/J3 -> 0.024072404 | S3: =Q3/G3 -> 0.20519885 | T3: =N3/G3 -> 0.10441917 | U3: =O3/G3 -> 0.11117136 | V3: =P3/G3 -> 0.094027484 | W3: =G3/J3 -> 0.048403196 | X3: =N3/J3 -> 0.0050542214 | Y3: =P3/J3 -> 0.0045512307
C4: 2018 | D4: 6.77 | E4: 3.4 | F4: 65.05 | G4: 34248.64 | H4: 16591.71 | I4: 18350.79 | J4: 494797.97 | K4: 17104.67 | L4: 1537.7 | M4: 10150.15 | N4: =L4+M4 -> 11687.85 | O4: 4909.84 | P4: 3853.15 | Q4: =O4+P4 -> 8762.99 | R4: =K4/J4 -> 0.034568998 | S4: =Q4/G4 -> 0.25586388 | T4: =N4/G4 -> 0.34126465 | U4: =O4/G4 -> 0.14335869 | V4: =P4/G4 -> 0.1125052 | W4: =G4/J4 -> 0.069217422 | X4: =N4/J4 -> 0.023621459 | Y4: =P4/J4 -> 0.0077873197
C5: 2019 | D5: 5.26 | E5: 2.06 | F5: 77 | G5: 29789.44 | H5: 11275.6 | I5: 20802.68 | J5: 571424.16 | K5: 9976.79 | L5: 1538.36 | M5: 7498.86 | N5: =L5+M5 -> 9037.22 | O5: 5073.6 | P5: 4027.24 | Q5: =O5+P5 -> 9100.84 | R5: =K5/J5 -> 0.017459517 | S5: =Q5/G5 -> 0.30550558 | T5: =N5/G5 -> 0.30336992 | U5: =O5/G5 -> 0.17031539 | V5: =P5/G5 -> 0.13519019 | W5: =G5/J5 -> 0.052131922 | X5: =N5/J5 -> 0.015815257 | Y5: =P5/J5 -> 0.0070477244
C6: 2020 | D6: 5.07 | E6: 1.63 | F6: 83 | G6: 30233.82 | H6: 9360.41 | I6: 18407.62 | J6: 623720.19 | K6: 12244.08 | L6: 2459.4 | M6: 7709.87 | N6: =L6+M6 -> 10169.27 | O6: 6586.14 | P6: 2715.22 | Q6: =O6+P6 -> 9301.36 | R6: =K6/J6 -> 0.019630726 | S6: =Q6/G6 -> 0.30764753 | T6: =N6/G6 -> 0.33635412 | U6: =O6/G6 -> 0.21784015 | V6: =P6/G6 -> 0.089807375 | W6: =G6/J6 -> 0.048473371 | X6: =N6/J6 -> 0.016304218 | Y6: =P6/J6 -> 0.0043532662
C7: 2021 | D7: 3.94 | E7: 1.14 | F7: 72 | G7: 25314.84 | H7: 6993.52 | I7: 16141.28 | J7: 707695.95 | K7: 11303.73 | L7: 3875.61 | M7: 10030.53 | N7: =L7+M7 -> 13906.14 | O7: 5264.77 | P7: 2994.67 | Q7: =O7+P7 -> 8259.44 | R7: =K7/J7 -> 0.01597258 | S7: =Q7/G7 -> 0.3262687 | T7: =N7/G7 -> 0.54932759 | U7: =O7/G7 -> 0.20797169 | V7: =P7/G7 -> 0.11829701 | W7: =G7/J7 -> 0.035770785 | X7: =N7/J7 -> 0.019649879 | Y7: =P7/J7 -> 0.0042315771
C8: 2022 | D8: 2.98 | E8: 0.77 | F8: 75 | G8: 21822.32 | H8: 5512.16 | I8: 14883.37 | J8: 845302.84 | K8: 7689.09 | L8: 1535.17 | M8: 7716.9 | N8: =L8+M8 -> 9252.07 | O8: 10990.39 | P8: 3359.81 | Q8: =O8+P8 -> 14350.2 | R8: =K8/J8 -> 0.0090962548 | S8: =Q8/G8 -> 0.65759278 | T8: =N8/G8 -> 0.42397279 | U8: =O8/G8 -> 0.50363069 | V8: =P8/G8 -> 0.15396209 | W8: =G8/J8 -> 0.025815979 | X8: =N8/J8 -> 0.010945273 | Y8: =P8/J8 -> 0.003974682
C9: 2023 | D9: 2.12 | E9: 0.42 | F9: 0 | G9: 18604.23 | H9: 3558.92 | I9: 11876.4 | J9: 965068.38 | K9: 6839.59 | L9: 1773.09 | M9: 5520.28 | N9: =L9+M9 -> 7293.37 | O9: 6600.53 | P9: 3969.22 | Q9: =O9+P9 -> 10569.75 | R9: =K9/J9 -> 0.0070871558 | S9: =Q9/G9 -> 0.56813692 | T9: =N9/G9 -> 0.39202751 | U9: =O9/G9 -> 0.35478652 | V9: =P9/G9 -> 0.2133504 | W9: =G9/J9 -> 0.019277629 | X9: =N9/J9 -> 0.0075573609 | Y9: =P9/J9 -> 0.0041128899
C10: 2024 | D10: 1.51 | E10: 0.33 | F10: 79 | G10: 15127.12 | H10: 3247.47 | I10: 10801.41 | J10: 1040811.3 | K10: 6371.05 | L10: 2896.01 | M10: 5968.9 | N10: =L10+M10 -> 8864.91 | O10: 6130.97 | P10: 2911.79 | Q10: =O10+P10 -> 9042.76 | R10: =K10/J10 -> 0.0061212343 | S10: =Q10/G10 -> 0.59778464 | T10: =N10/G10 -> 0.58602761 | U10: =O10/G10 -> 0.40529658 | V10: =P10/G10 -> 0.19248806 | W10: =G10/J10 -> 0.01453397 | X10: =N10/J10 -> 0.0085173074 | Y10: =P10/J10 -> 0.0027976156
C11: 2025 | D11: 1.36 | E11: 0.35 | F11: 75 | G11: 15127.12 | H11: 3685.45 | I11: 10801.41 | J11: 1040811.3 | K11: 12138.53 | L11: 5007.96 | M11: 6824.31 | N11: =L11+M11 -> 11832.27 | O11: 4626.58 | P11: 3651.82 | Q11: =O11+P11 -> 8278.4 | R11: =K11/J11 -> 0.011662565 | S11: =Q11/G11 -> 0.54725553 | T11: =N11/G11 -> 0.78218921 | U11: =O11/G11 -> 0.30584672 | V11: =P11/G11 -> 0.24140881 | W11: =G11/J11 -> 0.01453397 | X11: =N11/J11 -> 0.011368314 | Y11: =P11/J11 -> 0.0035086282
B12: ICICI Bank Ltd. | C12: 2016 | D12: 5.82 | E12: 2.98 | F12: 50.6 | G12: 26221.25 | H12: 12963.08 | I12: 16942.58 | J12: 464232.08 | K12: 8073.2 | L12: 927.76 | M12: 2027.58 | N12: =L12+M12 -> 2955.34 | O12: 1123.98 | P12: 1504.97 | Q12: =O12+P12 -> 2628.95 | R12: =K12/J12 -> 0.01739044 | S12: =Q12/G12 -> 0.10026029 | T12: =N12/G12 -> 0.11270782 | U12: =O12/G12 -> 0.042865233 | V12: =P12/G12 -> 0.057395052 | W12: =G12/J12 -> 0.056483063 | X12: =N12/J12 -> 0.0063660831 | Y12: =P12/J12 -> 0.0032418483
C13: 2017 | D13: 7.89 | E13: 4.89 | F13: 40.2 | G13: 42159.39 | H13: 25216.81 | I13: 25416.62 | J13: 512395.29 | K13: 16160.44 | L13: 4906.13 | M13: 7285.78 | N13: =L13+M13 -> 12191.91 | O13: 970.34 | P13: 4446.22 | Q13: =O13+P13 -> 5416.56 | R13: =K13/J13 -> 0.03153901 | S13: =Q13/G13 -> 0.12847814 | T13: =N13/G13 -> 0.28918611 | U13: =O13/G13 -> 0.023015988 | V13: =P13/G13 -> 0.10546215 | W13: =G13/J13 -> 0.082279035 | X13: =N13/J13 -> 0.023793954 | Y13: =P13/J13 -> 0.0086773241
C14: 2018 | D14: 8.84 | E14: 4.77 | F14: 47.7 | G14: 53240.18 | H14: 27823.56 | I14: 32226.32 | J14: 586646.58 | K14: 19864.95 | L14: 1596.59 | M14: 6772.07 | N14: =L14+M14 -> 8368.66 | O14: 3866.82 | P14: 5318.68 | Q14: =O14+P14 -> 9185.5 | R14: =K14/J14 -> 0.03386187 | S14: =Q14/G14 -> 0.17252947 | T14: =N14/G14 -> 0.15718692 | U14: =O14/G14 -> 0.072629732 | V14: =P14/G14 -> 0.099899737 | W14: =G14/J14 -> 0.090753414 | X14: =N14/J14 -> 0.01426525 | Y14: =P14/J14 -> 0.0090662422
C15: 2019 | D15: 6.7 | E15: 2.06 | F15: 80.7 | G15: 45676.04 | H15: 13449.72 | I15: 30905.85 | J15: 645289.97 | K15: 19739.14 | L15: 1293.29 | M15: 10263.84 | N15: =L15+M15 -> 11557.13 | O15: 1190.36 | P15: 5412.61 | Q15: =O15+P15 -> 6602.97 | R15: =K15/J15 -> 0.030589566 | S15: =Q15/G15 -> 0.14456091 | T15: =N15/G15 -> 0.2530239 | U15: =O15/G15 -> 0.026060928 | V15: =P15/G15 -> 0.11849998 | W15: =G15/J15 -> 0.070783744 | X15: =N15/J15 -> 0.017909979 | Y15: =P15/J15 -> 0.0083878725
C16: 2020 | D16: 5.53 | E16: 1.41 | F16: 86.8 | G16: 40829.09 | H16: 9923.24 | I16: 31723.58 | J16: 733729.09 | K16: 14186.24 | L16: 682.15 | M16: 10269.71 | N16: =L16+M16 -> 10951.86 | O16: 1154.21 | P16: 6542.88 | Q16: =O16+P16 -> 7697.09 | R16: =K16/J16 -> 0.019334439 | S16: =Q16/G16 -> 0.18851975 | T16: =N16/G16 -> 0.26823669 | U16: =O16/G16 -> 0.028269305 | V16: =P16/G16 -> 0.16025045 | W16: =G16/J16 -> 0.055646001 | X16: =N16/J16 -> 0.014926299 | Y16: =P16/J16 -> 0.0089172967
C17: 2021 | D17: 4.96 | E17: 1.14 | F17: 77.7 | G17: 40841.42 | H17: 9117.66 | I17: 26363.69 | J17: 859020.44 | K17: 13351.53 | L17: 365.14 | M17: 9141.49 | N17: =L17+M17 -> 9506.63 | O17: 1754.62 | P17: 4774.64 | Q17: =O17+P17 -> 6529.26 | R17: =K17/J17 -> 0.015542738 | S17: =Q17/G17 -> 0.15986858 | T17: =N17/G17 -> 0.23276933 | U17: =O17/G17 -> 0.042961778 | V17: =P17/G17 -> 0.11690681 | W17: =G17/J17 -> 0.047544177 | X17: =N17/J17 -> 0.011066826 | Y17: =P17/J17 -> 0.0055582379
C18: 2022 | D18: 3.6 | E18: 0.76 | F18: 79.2 | G18: 33294.92 | H18: 6931.04 | I18: 24835.81 | J18: 1019638.3 | K18: 12188.33 | L18: 988 | M18: 9159.79 | N18: =L18+M18 -> 10147.79 | O18: 10443.82 | P18: 6245.9 | Q18: =O18+P18 -> 16689.72 | R18: =K18/J18 -> 0.011953582 | S18: =Q18/G18 -> 0.50126926 | T18: =N18/G18 -> 0.30478493 | U18: =O18/G18 -> 0.31367608 | V18: =P18/G18 -> 0.18759318 | W18: =G18/J18 -> 0.032653657 | X18: =N18/J18 -> 0.0099523428 | Y18: =P18/J18 -> 0.0061256035
C19: 2023 | D19: 2.81 | E19: 0.48 | F19: 82.8 | G19: 29986.07 | H19: 5150.07 | I19: 21935.88 | J19: 1184406.4 | K19: 11617.08 | L19: 942.34 | M19: 3578.86 | N19: =L19+M19 -> 4521.2 | O19: 9062.93 | P19: 8034.1 | Q19: =O19+P19 -> 17097.03 | R19: =K19/J19 -> 0.0098083564 | S19: =Q19/G19 -> 0.57016575 | T19: =N19/G19 -> 0.15077668 | U19: =O19/G19 -> 0.30223801 | V19: =P19/G19 -> 0.26792774 | W19: =G19/J19 -> 0.025317383 | X19: =N19/J19 -> 0.0038172709 | Y19: =P19/J19 -> 0.0067832292
C20: 2024 | D20: 2.16 | E20: 0.42 | F20: 80.3 | G20: 27313.87 | H20: 5377.79 | I20: 17933.5 | J20: 1341766.2 | K20: 11851.22 | L20: 931.32 | M20: 5266.93 | N20: =L20+M20 -> 6198.25 | O20: 9229.93 | P20: 6242.81 | Q20: =O20+P20 -> 15472.74 | R20: =K20/J20 -> 0.0088325525 | S20: =Q20/G20 -> 0.56647923 | T20: =N20/G20 -> 0.22692683 | U20: =O20/G20 -> 0.33792099 | V20: =P20/G20 -> 0.22855824 | W20: =G20/J20 -> 0.020356654 | X20: =N20/J20 -> 0.0046194711 | Y20: =P20/J20 -> 0.0046526811
